Workbook

Sheet DCF
B3: Discounted Cashflow Model
B4: CapMan Oyj | D4: NSDQ: HEL
B6: Year | C6: 2021A | D6: 2022A | E6: 2023A | F6: 2024A | G6: 2025A | H6: 2026E | I6: 2027E | J6: 2028E | K6: 2029E | L6: 2030E | M6: 2031E | N6: 2032E
B7: Revenue | C7: 46 | D7: 58.9 | E7: 49.305 | F7: 57.621 | G7: 63 | H7: =AUM!P24 -> 67.54275 | I7: =AUM!Q24 -> 78.206 | J7: =AUM!R24 -> 80.976 | K7: =AUM!S24 -> 84.75726 | L7: =AUM!T24 -> 87.965623 | M7: =AUM!U24 -> 90.511809 | N7: =AUM!V24 -> 92.727285
B8: Reported EBIT | C8: 39.7 | D8: 47.6 | E8: -1.2 | F8: 16.7 | G8: 23.2 | H8: =AUM!P30 -> 25.55275 | I8: =AUM!Q30 -> 33.686 | J8: =AUM!R30 -> 33.891 | K8: =AUM!S30 -> 35.913885 | L8: =AUM!T30 -> 37.407296 | M8: =AUM!U30 -> 38.385673 | N8: =AUM!V30 -> 39.028362
B9: (R) EBIT-% | C9: =C8/C7 -> 0.86304348 | D9: =D8/D7 -> 0.80814941 | E9: =E8/E7 -> -0.024338302 | F9: =F8/F7 -> 0.28982489 | G9: =G8/G7 -> 0.36825397 | H9: =H8/H7 -> 0.37831966 | I9: =I8/I7 -> 0.43073421 | J9: =J8/J7 -> 0.41853142 | ... N9: =N8/N7 -> 0.42089404
B10: Fair value adj. | C10: 33.9 | D10: 36.5 | E10: -6.1 | F10: 7.8 | G10: 15.5 | H10: =AUM!P29 -> 17.3 | I10: =AUM!Q29 -> 17.3 | J10: =AUM!R29 -> 17.3 | K10: =AUM!S29 -> 17.3 | L10: =AUM!T29 -> 17.3 | M10: =AUM!U29 -> 17.3 | N10: =AUM!V29 -> 17.3
B11: Operative EBIT | C11: =C8-C10 -> 5.8 | D11: =D8-D10 -> 11.1 | E11: =E8-E10 -> 4.9 | F11: =F8-F10 -> 8.9 | G11: =G8-G10 -> 7.7 | H11: =AUM!P28 -> 8.25275 | I11: =AUM!Q28 -> 16.386 | J11: =AUM!R28 -> 16.591 | K11: =AUM!S28 -> 18.613885 | L11: =AUM!T28 -> 20.107296 | M11: =AUM!U28 -> 21.085673 | N11: =AUM!V28 -> 21.728362
B12: (O) EBIT-% | C12: =C11/C7 -> 0.12608696 | D12: =D11/D7 -> 0.18845501 | E12: =E11/E7 -> 0.099381401 | F12: =F11/F7 -> 0.15445758 | G12: =G11/G7 -> 0.12222222 | H12: =H11/H7 -> 0.12218558 | I12: =I11/I7 -> 0.20952357 | J12: =J11/J7 -> 0.20488787 | ... N12: =N11/N7 -> 0.23432544
B13: NOPAT | C13: =C11*(1-$C$31) -> 4.64 | D13: =D11*(1-$C$31) -> 8.88 | E13: =E11*(1-$C$31) -> 3.92 | F13: =F11*(1-$C$31) -> 7.12 | G13: =G11*(1-$C$31) -> 6.16 | H13: =H11*(1-$C$31) -> 6.6022 | I13: =I11*(1-$C$31) -> 13.1088 | J13: =J11*(1-$C$31) -> 13.2728 | ... N13: =N11*(1-$C$31) -> 17.382689
B14: D&A | C14: 1.476 | D14: 1.58 | E14: 1.393 | F14: 2.445 | G14: 3 | H14: 3.2 | I14: 3.2 | J14: 3.2 | K14: 3.2 | L14: 3.2 | M14: 3.2 | N14: 3.2
B15: CAPEX | C15: -0.14 | D15: -0.333 | E15: -0.026 | F15: -0.047 | G15: -0.01 | H15: =-0.013*2 -> -0.026 | I15: =H15*1.05 -> -0.0273 | J15: =I15*1.05 -> -0.028665 | K15: =J15*1.05 -> -0.03009825 | L15: =K15*1.05 -> -0.031603163 | M15: =L15*1.05 -> -0.033183321 | N15: =M15*1.05 -> -0.034842487
B16: Δ NWC | D16: 3.77 | E16: =-3.773-2.271 -> -6.044 | F16: =7.982-(-3.773) -> 11.755 | G16: =6.777-7.982 -> -1.205 | H16: 0.52 | I16: =67.2*52%-58.62*44%-7.3 -> 1.8512 | J16: =72.1*52%-61.19*44%-9.15 -> 1.4184 | K16: 1.1 | L16: 0.8 | M16: 0.51 | N16: 0.4
B17: FCFF | C17: =C13+C14+C15-C16 -> 5.976 | D17: =D13+D14+D15-D16 -> 6.357 | E17: =E13+E14+E15-E16 -> 11.331 | F17: =F13+F14+F15-F16 -> -2.237 | G17: =G13+G14+G15-G16 -> 10.355 | H17: =H13+H14+H15-H16 -> 9.2562 | I17: =I13+I14+I15-I16 -> 14.4303 | J17: =J13+J14+J15-J16 -> 15.025735 | ... N17: =N13+N14+N15-N16 -> 20.147847
B19: Operating KPIs | F19: Revenue CAGR (21-25) | H19: =((G22/C22)^(1/4))-1 -> 0.081796768 | J19: Rvn. CAGR (26-32) | L19: =((N22/H22)^(1/6))-1 -> 0.054236708
B21: Year | C21: 2021 | D21: 2022 | E21: 2023 | F21: 2024 | G21: 2025 | H21: 2026e | I21: 2027e | J21: 2028e | K21: 2029e | L21: 2030e | M21: 2031e | N21: 2032e
B22: Revenue | C22: =C7 -> 46 | D22: =D7 -> 58.9 | E22: =E7 -> 49.305 | F22: =F7 -> 57.621 | G22: =G7 -> 63 | H22: =H7 -> 67.54275 | I22: =I7 -> 78.206 | J22: =J7 -> 80.976 | ... N22: =N7 -> 92.727285
B23: Growth | C23: - | D23: =D22/C22-1 -> 0.28043478 | E23: =E22/D22-1 -> -0.16290323 | F23: =F22/E22-1 -> 0.16866444 | G23: =G22/F22-1 -> 0.093351382 | H23: =H22/G22-1 -> 0.072107143 | I23: =I22/H22-1 -> 0.15787409 | J23: =J22/I22-1 -> 0.035419277 | K23: =K22/J22-1 -> 0.046696058 | ... N23: =N22/M22-1 -> 0.024477203
B24: Op. EBIT-% | C24: =C12 -> 0.12608696 | D24: =D12 -> 0.18845501 | E24: =E12 -> 0.099381401 | F24: =F12 -> 0.15445758 | G24: =G12 -> 0.12222222 | H24: =H12 -> 0.12218558 | I24: =I12 -> 0.20952357 | J24: =J12 -> 0.20488787 | ... N24: =N12 -> 0.23432544
B25: Margin change | C25: - | D25: 6.2 | E25: -8.9 | F25: 5.5 | G25: -3.2 | H25: 0 | I25: 8.5 | J25: -0.5 | K25: 1.5 | L25: 0.9 | M25: 0.4 | N25: 0.1
B26: FCFF Margin | C26: =C17/C7 -> 0.12991304 | D26: =D17/D7 -> 0.10792869 | E26: =E17/E7 -> 0.22981442 | F26: =F17/F7 -> -0.038822651 | G26: =G17/G7 -> 0.16436508 | H26: =H17/H7 -> 0.1370421 | I26: =I17/I7 -> 0.18451653 | J26: =J17/J7 -> 0.18555788 | ... N26: =N17/N7 -> 0.21728067
B29: DCF Valuation | G29: DF | H29: 1 | I29: 2 | J29: 3 | K29: 4 | L29: 5 | M29: 6 | N29: 7
G30: Year | H30: 2026e | I30: 2027e | J30: 2028e | K30: 2029e | L30: 2030e | M30: 2031e | N30: 2032e
B31: Tax rate | C31: 0.2 | G31: FCFF | H31: =H17 -> 9.2562 | I31: =I17 -> 14.4303 | J31: =J17 -> 15.025735 | K31: =K17 -> 16.96101 | L31: =L17 -> 18.454234 | M31: =M17 -> 19.525355 | N31: =N17 -> 20.147847
B32: TG | C32: 0.02 | G32: DCF | H32: =H31/(1+$C$33)^H29 -> 8.5538742 | I32: =I31/(1+$C$33)^I29 -> 12.323544 | J32: =J31/(1+$C$33)^J29 -> 11.8584 | K32: =K31/(1+$C$33)^K29 -> 12.370072 | L32: =L31/(1+$C$33)^L29 -> 12.437889 | M32: =M31/(1+$C$33)^M29 -> 12.161292 | N32: =N31/(1+$C$33)^N29 -> 11.596837
B33: WACC | C33: ='Capital structure'!J15 -> 0.082106165 | G33: Total DCF | H33: =H32+I32+J32+K32+L32+M32+N32 -> 81.301907
B34: DCF 2033 | C34: =N17*(1+C32) -> 20.550804 | G34: Terminal | H34: =C34/(C33-C32) -> 330.89796
B35: Shares | C35: =Overview!B19 -> 177.18 | G35: Present TV | H35: =H34/(1+C33)^N29 -> 190.46053
B36: Net Debt | C36: =Overview!B18 -> 60.39 | G36: Fee EV | H36: =H35+H33 -> 271.76244
G37: TV / Fee EV | H37: =H35/H36 -> 0.70083464
B39: Fee Enterprise Value | D39: =H33+H35 -> 271.76244 | G39: Sensitivity Analysis
B40: Rahastot NAV | C40: 46203 | D40: 173
B41: Lyhytaikaiset rahoitusvarat | D41: 5.6 | G41: =D46 -> 2.1759196 | H41: 0.01 | I41: 0.015 | J41: 0.02 | K41: 0.025 | L41: 0.03 | M41: TG
B42: Muut rahoitusvarat | D42: 0.71 | G42: 0.07 | H42: 2.314882 | I42: 2.4296887 | J42: 2.5674568 | K42: 2.73584 | L42: 2.946319
B43: Vähemmistöosuus | D43: 5.153 | G43: 0.08 | H43: 2.0620123 | I43: 2.1407586 | J43: 2.2326293 | K43: 2.3412037 | L43: 2.471493
B44: Net Debt | D44: =Overview!B18 -> 60.39 | G44: 0.09 | H44: 1.8728296 | I44: 1.9293329 | J44: 1.9939081 | K44: 2.0684179 | L44: 2.1553461
B45: Equity Value | D45: =D39+D40+D41+D42-C36-D43 -> 385.52944 | G45: 0.1 | H45: 1.7260829 | I45: 1.7680362 | J45: 1.8152337 | K45: 1.8687242 | L45: 1.9298562
B46: Osake / Fair value | D46: =D45/C35 -> 2.1759196 | G46: 0.11 | H46: 1.6090228 | I46: 1.6410208 | J46: 1.6765741 | K46: 1.7163101 | L46: 1.7610132
G47: WACC
B48: Current Share Value | D48: =Overview!B2 -> 1.75
...

Sheet AUM
C4: Modeling CapMan Oyj
C6: Assets Under Management | F6: Management target: 10 000 M€
C8: M (EUR) | D8: 31.12.24 A | E8: 31.12.25 A | F8: 31.3.26 A | G8: 2026 E | H8: 2027 E | I8: 2028 E
C9: Kiinteistösijoitukset | D9: 3090 | E9: 3754 | F9: 3794 | G9: =G10+200 -> 3994 | H9: =G9+350 -> 4344 | I9: =H9+150 -> 4494 | O9: Management Fee Model
C10: Beginning AUM | E10: =D9 -> 3090 | F10: =E9 -> 3754 | G10: =F9 -> 3794 | H10: =G9 -> 3994 | I10: =H10+350 -> 4344 | O10: Omaisuusluokka | P10: AUM avg. 26E | Q10: 27E | R10: 28E | S10: Fee rate | T10: Fee 26 | U10: Fee 27 | V10: Fee 28
C11: Net change | E11: =E9-D9 -> 664 | F11: =F9-E9 -> 40 | G11: =G9-F9 -> 200 | H11: =H9-G9 -> 350 | I11: =I9-H9 -> 150 | O11: Kiinteistösijoitukset | P11: =3/12*AVERAGE(E9,F9)+9/12*AVERAGE(F9,G9) -> 3864 | Q11: =AVERAGE(H10,H9) -> 4169 | R11: =AVERAGE(I10,I9) -> 4419 | S11: 0.007 | T11: =$S$11*P11 -> 27.048 | U11: =$S$11*Q11 -> 29.183 | V11: =$S$11*R11 -> 30.933
C12: Growth | E12: =E11/D9 -> 0.21488673 | F12: =F11/E9 -> 0.010655301 | G12: =G11/F9 -> 0.052714813 | H12: =H11/G9 -> 0.087631447 | I12: =I11/H9 -> 0.034530387 | O12: PE & Credit | P12: =3/12*AVERAGE(E13,F13)+9/12*AVERAGE(F13,G13) -> 940.375 | Q12: =AVERAGE(H14,H13) -> 965 | R12: =AVERAGE(I14,I13) -> 985 | S12: 0.01 | T12: =$S$12*P12 -> 9.40375 | U12: =$S$12*Q12 -> 9.65 | V12: =$S$12*R12 -> 9.85
C13: Private Equity & Credit | D13: 1080 | E13: 918 | F13: 935 | G13: =F13+20 -> 955 | H13: =G13+20 -> 975 | I13: =H13+20 -> 995 | O13: Natural Capital | P13: =3/12*AVERAGE(E17,F17)+9/12*AVERAGE(F17,G17) -> 788.25 | Q13: =AVERAGE(H18,H17) -> 870 | R13: =AVERAGE(I18,I17) -> 950 | S13: 0.008 | T13: =$S$13*P13 -> 6.306 | U13: =$S$13*Q13 -> 6.96 | V13: =$S$13*R13 -> 7.6
C14: Beginning AUM | E14: =D13 -> 1080 | F14: =E13 -> 918 | G14: =F13 -> 935 | H14: =G13 -> 955 | I14: =H13 -> 975 | O14: Real Asset Debt | P14: =3/12*AVERAGE(E21,F21)+9/12*AVERAGE(F21,G21) -> 598.125 | Q14: =AVERAGE(H22,H21) -> 660 | R14: =AVERAGE(I22,I21) -> 740 | S14: 0.007 | T14: =$S$14*P14 -> 4.186875 | U14: =$S$14*Q14 -> 4.62 | V14: =$S$14*R14 -> 5.18
C15: Net change | E15: =E13-D13 -> -162 | F15: =F13-E13 -> 17 | G15: =G13-F13 -> 20 | H15: =H13-G13 -> 20 | I15: =I13-H13 -> 20 | O15: Infrastruktuuri | P15: =3/12*AVERAGE(E25,F25)+9/12*AVERAGE(F25,G25) -> 651.625 | Q15: =AVERAGE(H26,H25) -> 931 | R15: =AVERAGE(I26,I25) -> 1091 | S15: 0.01 | T15: =$S$15*P15 -> 6.51625 | U15: =$S$15*Q15 -> 9.31 | V15: =$S$15*R15 -> 10.91
C16: Growth | E16: =E15/D13 -> -0.15 | F16: =F15/E13 -> 0.018518519 | G16: =G15/F13 -> 0.021390374 | H16: =H15/G13 -> 0.020942408 | I16: =I15/H13 -> 0.020512821 | O16: Varainhoito | P16: =3/12*AVERAGE(E29,F29)+9/12*AVERAGE(F29,G29) -> 633.5 | Q16: =AVERAGE(H30,H29) -> 703 | R16: =AVERAGE(I30,I29) -> 733 | S16: - | T16: 8.5 | U16: 8.7 | V16: 8.9
C17: Luontopääomasijoitukset | D17: 726 | E17: 816 | F17: 750 | G17: =F17+80 -> 830 | H17: =G17+80 -> 910 | I17: =H17+80 -> 990 | O17: Total M€ | P17: =SUM(P11:P16) -> 7475.875 | Q17: =SUM(Q11:Q16) -> 8298 | R17: =SUM(R11:R16) -> 8918 | S17: Total fees | T17: =SUM(T11:T16) -> 61.960875 | U17: =SUM(U11:U16) -> 68.423 | V17: =SUM(V11:V16) -> 73.373
C18: Beginning AUM | E18: =D17 -> 726 | F18: =E17 -> 816 | G18: =F17 -> 750 | H18: =G17 -> 830 | I18: =H17 -> 910
C19: Net change | E19: =E17-D17 -> 90 | F19: =F17-E17 -> -66 | G19: =G17-F17 -> 80 | H19: =H17-G17 -> 80 | I19: =I17-H17 -> 80 | O19: Valuation
C20: Growth | E20: =E19/D17 -> 0.12396694 | F20: =F19/E17 -> -0.080882353 | G20: =G19/F17 -> 0.10666667 | H20: =H19/G17 -> 0.096385542 | I20: =I19/H17 -> 0.087912088 | O20: M€ | P20: 2026E | Q20: 2027E | R20: 2028E | S20: 2029E | T20: 2030E | U20: 2031E | V20: 2032E
C21: Real Asset Debt - sijoitukset | D21: N/A | E21: 585 | F21: 585 | G21: =F21+35 -> 620 | H21: =G21+80 -> 700 | I21: =H21+80 -> 780 | O21: Palkkiotuotot | P21: 61.54275 | Q21: 67.208 | R21: 72.058 | S21: =R21*1.05 -> 75.6609 | T21: =S21*1.04 -> 78.687336 | U21: =T21*1.03 -> 81.047956 | V21: =U21*1.025 -> 83.074155
C22: Beginning AUM | F22: =E21 -> 585 | G22: =F21 -> 585 | H22: =G21 -> 620 | I22: =H21 -> 700 | O22: Catch -up fees | P22: 0 | Q22: 2.7 | R22: 0 | S22: 0 | T22: 0 | U22: 0 | V22: 0
C23: Net change | F23: =F21-F22 -> 0 | G23: =G21-G22 -> 35 | H23: =H21-H22 -> 80 | I23: =I21-I22 -> 80 | O23: Voitonjako-osuustuotot | P23: 6 | Q23: =0.1%*Q17 -> 8.298 | R23: =0.1%*R17 -> 8.918 | S23: =R23*1.02 -> 9.09636 | T23: =S23*1.02 -> 9.2782872 | U23: =T23*1.02 -> 9.4638529 | V23: =U23*1.02 -> 9.65313
C24: Growth | F24: =F23/E21 -> 0 | G24: =G23/F21 -> 0.05982906 | H24: =H23/G21 -> 0.12903226 | I24: =I23/H21 -> 0.11428571 | O24: Liikevaihto | P24: =SUM(P21:P23) -> 67.54275 | Q24: =SUM(Q21:Q23) -> 78.206 | R24: =SUM(R21:R23) -> 80.976 | S24: =SUM(S21:S23) -> 84.75726 | T24: =SUM(T21:T23) -> 87.965623 | U24: =SUM(U21:U23) -> 90.511809 | V24: =SUM(V21:V23) -> 92.727285
C25: Infrasijoitukset | D25: 648 | E25: 554 | F25: 549 | G25: =F25+272 -> 821 | H25: =G25+220 -> 1041 | I25: =H25+100 -> 1141 | O25: Henkilöstökulut | P25: =(183*230)/1000 -> 42.09 | Q25: =(183*240)/1000 -> 43.92 | R25: =(183*250)/1000 -> 45.75 | S25: =R25*1.03 -> 47.1225 | T25: =S25*1.028 -> 48.44193 | U25: =T25*1.025 -> 49.652978 | V25: =U25*1.025 -> 50.894303
C26: Beginning AUM | E26: =D25 -> 648 | F26: =E25 -> 554 | G26: =F25 -> 549 | H26: =G25 -> 821 | I26: =H25 -> 1041 | O26: Muut kulut | P26: =3.5*4 -> 14 | Q26: =P26*1.05 -> 14.7 | R26: =Q26*1.05 -> 15.435 | S26: =R26*1.025 -> 15.820875 | T26: =S26*1.025 -> 16.216397 | U26: =T26*1.022 -> 16.573158 | V26: =U26*1.02 -> 16.904621
C27: Net change | E27: =E25-E26 -> -94 | F27: =F25-F26 -> -5 | G27: =G25-G26 -> 272 | H27: =H25-H26 -> 220 | I27: =I25-I26 -> 100 | O27: Poistot | P27: 3.2 | Q27: 3.2 | R27: 3.2 | S27: 3.2 | T27: 3.2 | U27: 3.2 | V27: 3.2
C28: Growth | E28: =E27/D25 -> -0.14506173 | F28: =F27/E25 -> -0.0090252708 | G28: =G27/F25 -> 0.49544627 | H28: =H27/G25 -> 0.2679659 | I28: =I27/H25 -> 0.096061479 | O28: EBIT | P28: =P24-P25-P26-P27 -> 8.25275 | Q28: =Q24-Q25-Q26-Q27 -> 16.386 | R28: =R24-R25-R26-R27 -> 16.591 | S28: =S24-S25-S26-S27 -> 18.613885 | T28: =T24-T25-T26-T27 -> 20.107296 | U28: =U24-U25-U26-U27 -> 21.085673 | V28: =V24-V25-V26-V27 -> 21.728362
C29: Varainhoito | D29: 518 | E29: 583 | F29: 609 | G29: =E29+100 -> 683 | H29: =G29+40 -> 723 | I29: =H29+20 -> 743 | O29: Käyvän arvon muutokset | P29: =173*0.1 -> 17.3 | Q29: =173*0.1 -> 17.3 | R29: =173*0.1 -> 17.3 | S29: =173*0.1 -> 17.3 | T29: =173*0.1 -> 17.3 | U29: =173*0.1 -> 17.3 | V29: =173*0.1 -> 17.3
C30: Beginning AUM | E30: =D29 -> 518 | F30: =E29 -> 583 | G30: =F29 -> 609 | H30: =G29 -> 683 | I30: =H29 -> 723 | O30: Reported Ebit | P30: =P29+P28 -> 25.55275 | Q30: =Q29+Q28 -> 33.686 | R30: =R29+R28 -> 33.891 | S30: =S29+S28 -> 35.913885 | T30: =T29+T28 -> 37.407296 | U30: =U29+U28 -> 38.385673 | V30: =V29+V28 -> 39.028362
C31: Net change | E31: =E29-E30 -> 65 | F31: =F29-F30 -> 26 | G31: =G29-G30 -> 74 | H31: =H29-H30 -> 40 | I31: =I29-I30 -> 20
C32: Growth | E32: =E31/D29 -> 0.12548263 | F32: =F31/E29 -> 0.044596913 | G32: =G31/F29 -> 0.12151067 | H32: =H31/G29 -> 0.058565154 | I32: =I31/H29 -> 0.027662517
C33: Hallinoitavat pääomat yhteensä | D33: =SUM(D9:D29) -> 6062 | E33: =E29+E25+E21+E17+E13+E9 -> 7210 | F33: =F29+F25+F21+F17+F13+F9 -> 7222 | G33: =G29+G25+G21+G17+G13+G9 -> 7903 | H33: =H29+H25+H21+H17+H13+H9 -> 8693 | I33: =I29+I25+I21+I17+I13+I9 -> 9143

Sheet Overview
A1: symbol | B1: currentPrice | C1: beta | D1: trailingPE | E1: priceToBook | F1: bookValue | G1: trailingEps | H1: quickRatio | I1: currentRatio | J1: returnOnEquity | K1: revenueGrowth
A2: CAPMAN.HE | B2: 1.75 | C2: 0.784 | D2: 25.34 | E2: 1.73 | F2: 1023 | G2: 0.07 | H2: 2.501 | I2: 2.501 | J2: 0.08 | K2: 0.252
A3: Imported from Yahoo Finance
A5: ROE & Volatility (yfinance) | D5: Capital Structure | G5: CAPMAN Oyj Daily Closing Price 2016 - 2026
A6: Metric | B6: Value | D6: WACC | E6: CAPM
A7: ROE (latest FY) | B7: 0.44 | D7: 0.0821 | E7: 0.0945
A8: ROE (prev FY) | B8: 0.07
A9: ROE 2y average | B9: 0.25 | D9: Financial figures | E9: 2026E
A10: Volatility 60d (ann.) | B10: 0.19446508 | D10: EV/EBITDA | E10: =B15/(DCF!H8+DCF!H14) -> 12.884159
A11: Volatility 252d (ann.) | B11: 0.212 | D11: EV/EBIT | E11: =B15/DCF!H8 -> 14.497657
D12: P/E | E12: =B2/0.13 -> 13.461538
A13: Market valuation & Information 2026 | D13: FCF Yield | E13: =DCF!H17/Overview!B15 -> 0.024986031
A14: Market Cap | B14: =B2*B19 -> 310.065 | D14: Dividend Yield | E14: =0.13/Overview!B2 -> 0.074285714
A15: Enterprise Value | B15: =B14+B18 -> 370.455 | D15: P/B Q2'26 | E15: =B14/181.9 -> 1.7045904
A16: Debt | B16: 105.6
A17: Cash | B17: 45.21
A18: Net Debt | B18: =B16-B17 -> 60.39
A19: Shares | B19: 177.18
A23: Model Updated | B23: 46236
E27: Beta 2y - OMX Helsinki
C28: Date | D28: CapMan close | E28: Market close | F28: CapMan Return | G28: Market Return | H28: Beta | I28: R2
C29: 45506 | D29: 1.842 | E29: 30770.41 | H29: =SLOPE(F29:F133,G29:G133) -> 0.78392359 | I29: =RSQ(F29:F133,G29:G133) -> 0.27058177
C30: 45513 | D30: 1.736 | E30: 31031.359 | F30: =D30/D29-1 -> -0.057546145 | G30: =E30/E29-1 -> 0.0084805246
C31: 45520 | D31: 1.802 | E31: 31675.5 | F31: =D31/D30-1 -> 0.038018433 | G31: =E31/E30-1 -> 0.020757731
C32: 45527 | D32: 1.816 | E32: 32266.369 | F32: =D32/D31-1 -> 0.0077691454 | G32: =E32/E31-1 -> 0.018653822
C33: 45534 | D33: 1.844 | E33: 32658.311 | F33: =D33/D32-1 -> 0.015418502 | G33: =E33/E32-1 -> 0.012147056
C34: 45541 | D34: 1.776 | E34: 31509.58 | F34: =D34/D33-1 -> -0.036876356 | G34: =E34/E33-1 -> -0.035174216
C35: 45548 | D35: 1.776 | E35: 31485.98 | F35: =D35/D34-1 -> 0 | G35: =E35/E34-1 -> -0.00074896615
C36: 45555 | D36: 1.774 | E36: 31821.58 | F36: =D36/D35-1 -> -0.0011261261 | G36: =E36/E35-1 -> 0.0106587
C37: 45562 | D37: 1.832 | E37: 33010.371 | F37: =D37/D36-1 -> 0.032694476 | G37: =E37/E36-1 -> 0.037358013
C38: 45569 | D38: 1.924 | E38: 32800.25 | F38: =D38/D37-1 -> 0.050218341 | G38: =E38/E37-1 -> -0.0063653054
C39: 45576 | D39: 1.89 | E39: 32536.609 | F39: =D39/D38-1 -> -0.017671518 | G39: =E39/E38-1 -> -0.0080377627
C40: 45583 | D40: 1.886 | E40: 32714.439 | F40: =D40/D39-1 -> -0.0021164021 | G40: =E40/E39-1 -> 0.0054655381
C41: 45590 | D41: 1.84 | E41: 32271.68 | F41: =D41/D40-1 -> -0.024390244 | G41: =E41/E40-1 -> -0.013534078
... C133: 46234 | D133: 1.772 | E133: 45670.77 | F133: =D133/D132-1 -> 0.017221584 | G133: =E133/E132-1 -> -0.00098391624

Sheet Comparable Analysis
B3: Comparable Company Analysis
B5: (M€) | C5: Figures: 2025 A
B6: Company | C6: Shares (M) | D6: Share price | E6: Market cap | F6: Net Debt | G6: EV | H6: Revenue | I6: EBIT | J6: Net profit | M6: EV/Revenue | N6: EV/EBIT | O6: P/E
B7: CapMan | C7: 176.8 | D7: 1.92 | E7: 339.6 | F7: 45.2 | G7: 384.8 | H7: 63 | I7: 23.2 | J7: 13.18 | M7: =G7/H7 -> 6.1079365 | N7: =G7/I7 -> 16.586207 | O7: =E7/J7 -> 25.766313
B8: eQ | C8: 41.4 | D8: 11.05 | E8: 457.4 | F8: -12.27 | G8: 445.3 | H8: 58.16 | I8: 27.391 | J8: 21.59 | M8: =G8/H8 -> 7.6564649 | N8: =G8/I8 -> 16.257165 | O8: =E8/J8 -> 21.185734
B9: Evli | C9: 26.49 | D9: 22.6 | E9: 598.6 | F9: 0 | G9: 598.6 | H9: 128.4 | I9: 56.1 | J9: 36.5 | M9: =G9/H9 -> 4.6619938 | N9: =G9/I9 -> 10.670232 | O9: =E9/J9 -> 16.4
B10: Taaleri | C10: 28.196 | D10: 7.81 | E10: 220.2 | F10: -10.685 | G10: 209.5 | H10: 63.66 | I10: 26.05 | J10: 16.61 | M10: =G10/H10 -> 3.2909205 | N10: =G10/I10 -> 8.0422265 | O10: =E10/J10 -> 13.257074
B11: United Bankers | C11: 10.97 | D11: 19.6 | E11: 215 | F11: 0 | G11: 215 | H11: 57.14 | I11: 16.64 | J11: 12.93 | M11: =G11/H11 -> 3.7626881 | N11: =G11/I11 -> 12.920673 | O11: =E11/J11 -> 16.627997
B12: Titanium | C12: 10.371 | D12: 7.1 | E12: 73.6 | F12: -12.313 | G12: 61.3 | H12: 20.2 | I12: 6.85 | J12: 5.32 | M12: =G12/H12 -> 3.0346535 | N12: =G12/I12 -> 8.9489051 | O12: =E12/J12 -> 13.834586
L13: Valuation
B14: CapMan Implied trading valuation (2025A results) | L14: High | M14: =MAX(M8:M12) -> 7.6564649 | N14: =MAX(N8:N12) -> 16.257165 | O14: =MAX(O8:O12) -> 21.185734
L15: 75th % | M15: =_xlfn.QUARTILE.EXC(M8:M12,3) -> 6.1592293 | N15: =_xlfn.QUARTILE.EXC(N8:N12,3) -> 14.588919 | O15: =_xlfn.QUARTILE.EXC(O8:O12,3) -> 18.906866
B16: Metric | C16: EV/Revenue | D16: EV/EBIT | E16: P/E | L16: Average | M16: =AVERAGE(M8:M12) -> 4.4813442 | N16: =AVERAGE(N8:N12) -> 11.36784 | O16: =AVERAGE(O8:O12) -> 16.261078
B17: Implied EV | C17: =M17*H7 -> 237.04935 | D17: =N17*I7 -> 247.54938 | E17: =O16*J7 -> 214.32101 | L17: Median | M17: =MEDIAN(M8:M12) -> 3.7626881 | N17: =MEDIAN(N8:N12) -> 10.670232 | O17: =MEDIAN(O8:O12) -> 16.4
B18: Net Debt | C18: =F7 -> 45.2 | D18: =F7 -> 45.2 | L18: 25th % | M18: =_xlfn.QUARTILE.EXC(M8:M12,1) -> 3.162787 | N18: =_xlfn.QUARTILE.EXC(N8:N12,1) -> 8.4955658 | O18: =_xlfn.QUARTILE.EXC(O8:O12,1) -> 13.54583
B19: Implied MV | C19: =C17-C18 -> 191.84935 | D19: =D17-D18 -> 202.34938 | E19: =E17-E18 -> 214.32101 | L19: Low | M19: =MIN(M8:M12) -> 3.0346535 | N19: =MIN(N8:N12) -> 8.0422265 | O19: =MIN(O8:O12) -> 13.257074
B20: Shares outstanding | C20: =$C$7 -> 176.8 | D20: =$C$7 -> 176.8 | E20: =$C$7 -> 176.8
B21: Implied value | C21: =C19/C20 -> 1.0851208 | D21: =D19/D20 -> 1.14451 | E21: =E19/E20 -> 1.2122229

Sheet Capital structure
B3: Weighted Average Cost of Capital | I3: Capital Asset Pricing Model
B4: CAPMAN Oyj
I5: Beta (Python Calc.) | K5: 0.784
B6: Issued Bonds | D6: Coupon | E6: Amount | I6: Risk Premium (PWC) | K6: 0.076
B7: 2022-2027 | D7: 0.045 | E7: 40 M € | I7: Risk Free Rate | K7: 0.0349
B8: 2024-2029 | D8: 0.065 | E8: 60 M € | I8: CAPM | K8: =$K$7+$K$5*($K$6) -> 0.094484
B10: Debt Structure | I10: WACC Calculation
B11: Bond 2022-2027 | D11: Bond 2024-2029 | I11: MC | J11: 313.07
B12: 40 | C12: M€ | D12: 60 | E12: M€ | I12: Debt | J12: 105.86
B13: 0.045 | C13: Coupon | D13: 0.065 | E13: Coupon | I13: CAPM | J13: =$K$7+$K$5*($K$6) -> 0.094484
B14: Q2/2027 | C14: Maturity | D14: Q2/2029 | E14: Maturity | I14: Kdat | J14: 0.0455
B15: 1013.34 | C15: MV | D15: 1009.08 | E15: MV | I15: WACC | J15: =J11/(J12+J11)*J13+(J12/(J12+J11)*J14) -> 0.082106165
B16: 1000 | C16: FV | D16: 1000 | E16: FV
B19: 22-27 | G19: 0.7
B20: Year | G20: 2027
B21: CF | G21: =$B$16*$B$13+B16 -> 1045
B22: DCF | G22: =G21/(1+$C$23)^G19 -> 1013.34
B23: Yield | C23: 0.044930226 | F23: Total DCF | G23: =SUM(C22:G22) -> 1013.34
B25: 24-29 | E25: 0.86 | F25: 1.86 | G25: 2.86
B26: Year | C26: 2025 | D26: 2026 | E26: 2027 | F26: 2028 | G26: 2029
B27: CF | E27: =$D$16*$D$13 -> 65 | F27: =$D$16*$D$13 -> 65 | G27: =$D$16*$D$13+1000 -> 1065
B28: DCF | E28: =E27/(1+$C$29)^E25 -> 61.577747 | F28: =F27/(1+$C$29)^F25 -> 57.824296 | G28: =G27/(1+$C$29)^G25 -> 889.67863
B29: Yield | C29: 0.06491132 | F29: Total DCF | G29: =SUM(D28:G28) -> 1009.0807
B31: Tax 20% | D31: Weight | F31: Rd (Kdat)
B32: Kdat 2022 | C32: =C23*(1-0.2) -> 0.035944181 | D32: 0.4 | F32: =C32*D32+C33*D33 -> 0.045535106
B33: Kdat 2024 | C33: =C29*(1-0.2) -> 0.051929056 | D33: 0.6

Sheet Monte Carlo
B4: Monte Carlo Simulation
B6: WACC | C6: =Overview!D7 -> 0.0821
B7: TG | C7: 0.02
B8: Net Debt | C8: =Overview!B18 -> 60.39
B9: Shares | C9: =Overview!B19 -> 177.18
B10: FCFF 2033 | C10: =DCF!C34 -> 20.550804
B11: 2026-2032 | C11: =DCF!H31 -> 9.2562 | D11: =DCF!I31 -> 14.4303 | E11: =DCF!J31 -> 15.025735 | F11: =DCF!K31 -> 16.96101 | G11: =DCF!L31 -> 18.454234 | H11: =DCF!M31 -> 19.525355 | I11: =DCF!N31 -> 20.147847
B12: DCF | C12: =DCF!H32 -> 8.5538742 | D12: =DCF!I32 -> 12.323544 | E12: =DCF!J32 -> 11.8584 | F12: =DCF!K32 -> 12.370072 | G12: =DCF!L32 -> 12.437889 | H12: =DCF!M32 -> 12.161292 | I12: =DCF!N32 -> 11.596837
B13: Time | C13: 1 | D13: 2 | E13: 3 | F13: 4 | G13: 5 | H13: 6 | I13: 7
C15: Rand | D15: WACC | E15: Rand | F15: G | G15: Rand | H15: Fair Value | J15: FV Median | K15: FV Average | L15: FV 0,05 | M15: FV 0,95 | N15: Min | O15: Max
C16: =RAND() -> 0.9003804 | D16: =IF(C16<($C$6-0.07)/(0.11-0.07),0.07+SQRT(C16*(0.11-0.07)*($C$6-0.07)),0.11-SQRT((1-C16)*(0.11-0.07)*(0.11-$C$6))) -> 0.099456022 | E16: =RAND() -> 0.81720944 | F16: =MIN( IF(E16<(0.02-0.01)/(0.03-0.01), 0.01+SQRT(E16*(0.03-0.01)*(0.02-0.01)), 0.03-SQRT((1-E16)*(0.03-0.01)*(0.03-0.02)) ), D16-0.005 ) -> 0.02395367 | G16: =$C$11/(1+D16)^1 +$D$11/(1+D16)^2 +$E$11/(1+D16)^3 +$F$11/(1+D16)^4 +$G$11/(1+D16)^5 +$H$11/(1+D16)^6 +$I$11/(1+D16)^7 + ( $I$11*(1+F16)/(D16-F16) )/(1+D16)^7 -> 216.88916 | H16: =(G16+DCF!$D$40+DCF!$D$41+DCF!$D$42-DCF!$D$43-DCF!$D$44)/DCF!$C$35 -> 1.866216 | J16: =MEDIAN(H16:H2016) -> 2.06018 | K16: =AVERAGE(H16:H2016) -> 2.0736332 | L16: =_xlfn.PERCENTILE.INC(H16:H2016,0.05) -> 1.7820751 | M16: =_xlfn.PERCENTILE.INC(H16:H2016,0.95) -> 2.4170118 | N16: =MIN(H16:H2016) -> 1.6520665 | O16: =MAX(H16:H2016) -> 2.7735117
C17: =RAND() -> 0.9980572 | D17: =IF(C17<($C$6-0.07)/(0.11-0.07),0.07+SQRT(C17*(0.11-0.07)*($C$6-0.07)),0.11-SQRT((1-C17)*(0.11-0.07)*(0.11-$C$6))) -> 0.10852753 | E17: =RAND() -> 0.787093 | F17: =MIN( IF(E17<(0.02-0.01)/(0.03-0.01), 0.01+SQRT(E17*(0.03-0.01)*(0.02-0.01)), 0.03-SQRT((1-E17)*(0.03-0.01)*(0.03-0.02)) ), D17-0.005 ) -> 0.023474558 | G17: =$C$11/(1+D17)^1 +$D$11/(1+D17)^2 +$E$11/(1+D17)^3 +$F$11/(1+D17)^4 +$G$11/(1+D17)^5 +$H$11/(1+D17)^6 +$I$11/(1+D17)^7 + ( $I$11*(1+F17)/(D17-F17) )/(1+D17)^7 -> 191.56457 | H17: =(G17+DCF!$D$40+DCF!$D$41+DCF!$D$42-DCF!$D$43-DCF!$D$44)/DCF!$C$35 -> 1.7232846
C18: =RAND() -> 0.47613958 | D18: =IF(C18<($C$6-0.07)/(0.11-0.07),0.07+SQRT(C18*(0.11-0.07)*($C$6-0.07)),0.11-SQRT((1-C18)*(0.11-0.07)*(0.11-$C$6))) -> 0.085820913 | E18: =RAND() -> 0.093689617 | F18: =MIN( IF(E18<(0.02-0.01)/(0.03-0.01), 0.01+SQRT(E18*(0.03-0.01)*(0.02-0.01)), 0.03-SQRT((1-E18)*(0.03-0.01)*(0.03-0.02)) ), D18-0.005 ) -> 0.014328732 | G18: =$C$11/(1+D18)^1 +$D$11/(1+D18)^2 +$E$11/(1+D18)^3 +$F$11/(1+D18)^4 +$G$11/(1+D18)^5 +$H$11/(1+D18)^6 +$I$11/(1+D18)^7 + ( $I$11*(1+F18)/(D18-F18) )/(1+D18)^7 -> 240.80051 | H18: =(G18+DCF!$D$40+DCF!$D$41+DCF!$D$42-DCF!$D$43-DCF!$D$44)/DCF!$C$35 -> 2.0011712
C19: =RAND() -> 0.14782857 | D19: =IF(C19<($C$6-0.07)/(0.11-0.07),0.07+SQRT(C19*(0.11-0.07)*($C$6-0.07)),0.11-SQRT((1-C19)*(0.11-0.07)*(0.11-$C$6))) -> 0.078458666 | E19: =RAND() -> 0.59449674 | F19: =MIN( IF(E19<(0.02-0.01)/(0.03-0.01), 0.01+SQRT(E19*(0.03-0.01)*(0.02-0.01)), 0.03-SQRT((1-E19)*(0.03-0.01)*(0.03-0.02)) ), D19-0.005 ) -> 0.02099441 | G19: =$C$11/(1+D19)^1 +$D$11/(1+D19)^2 +$E$11/(1+D19)^3 +$F$11/(1+D19)^4 +$G$11/(1+D19)^5 +$H$11/(1+D19)^6 +$I$11/(1+D19)^7 + ( $I$11*(1+F19)/(D19-F19) )/(1+D19)^7 -> 293.41563 | H19: =(G19+DCF!$D$40+DCF!$D$41+DCF!$D$42-DCF!$D$43-DCF!$D$44)/DCF!$C$35 -> 2.2981298
C20: =RAND() -> 0.87207505 | D20: =IF(C20<($C$6-0.07)/(0.11-0.07),0.07+SQRT(C20*(0.11-0.07)*($C$6-0.07)),0.11-SQRT((1-C20)*(0.11-0.07)*(0.11-$C$6))) -> 0.098051601 | E20: =RAND() -> 0.63634085 | F20: =MIN( IF(E20<(0.02-0.01)/(0.03-0.01), 0.01+SQRT(E20*(0.03-0.01)*(0.02-0.01)), 0.03-SQRT((1-E20)*(0.03-0.01)*(0.03-0.02)) ), D20-0.005 ) -> 0.021471704 | G20: =$C$11/(1+D20)^1 +$D$11/(1+D20)^2 +$E$11/(1+D20)^3 +$F$11/(1+D20)^4 +$G$11/(1+D20)^5 +$H$11/(1+D20)^6 +$I$11/(1+D20)^7 + ( $I$11*(1+F20)/(D20-F20) )/(1+D20)^7 -> 216.2131 | H20: =(G20+DCF!$D$40+DCF!$D$41+DCF!$D$42-DCF!$D$43-DCF!$D$44)/DCF!$C$35 -> 1.8624004
C21: =RAND() -> 0.96070831 | D21: =IF(C21<($C$6-0.07)/(0.11-0.07),0.07+SQRT(C21*(0.11-0.07)*($C$6-0.07)),0.11-SQRT((1-C21)*(0.11-0.07)*(0.11-$C$6))) -> 0.1033781 | E21: =RAND() -> 0.44330296 | F21: =MIN( IF(E21<(0.02-0.01)/(0.03-0.01), 0.01+SQRT(E21*(0.03-0.01)*(0.02-0.01)), 0.03-SQRT((1-E21)*(0.03-0.01)*(0.03-0.02)) ), D21-0.005 ) -> 0.019415975 | G21: =$C$11/(1+D21)^1 +$D$11/(1+D21)^2 +$E$11/(1+D21)^3 +$F$11/(1+D21)^4 +$G$11/(1+D21)^5 +$H$11/(1+D21)^6 +$I$11/(1+D21)^7 + ( $I$11*(1+F21)/(D21-F21) )/(1+D21)^7 -> 197.9598 | H21: =(G21+DCF!$D$40+DCF!$D$41+DCF!$D$42-DCF!$D$43-DCF!$D$44)/DCF!$C$35 -> 1.7593792
C22: =RAND() -> 0.5374804 | D22: =IF(C22<($C$6-0.07)/(0.11-0.07),0.07+SQRT(C22*(0.11-0.07)*($C$6-0.07)),0.11-SQRT((1-C22)*(0.11-0.07)*(0.11-$C$6))) -> 0.087280584 | E22: =RAND() -> 0.030947709 | F22: =MIN( IF(E22<(0.02-0.01)/(0.03-0.01), 0.01+SQRT(E22*(0.03-0.01)*(0.02-0.01)), 0.03-SQRT((1-E22)*(0.03-0.01)*(0.03-0.02)) ), D22-0.005 ) -> 0.012487879 | G22: =$C$11/(1+D22)^1 +$D$11/(1+D22)^2 +$E$11/(1+D22)^3 +$F$11/(1+D22)^4 +$G$11/(1+D22)^5 +$H$11/(1+D22)^6 +$I$11/(1+D22)^7 + ( $I$11*(1+F22)/(D22-F22) )/(1+D22)^7 -> 231.55828 | H22: =(G22+DCF!$D$40+DCF!$D$41+DCF!$D$42-DCF!$D$43-DCF!$D$44)/DCF!$C$35 -> 1.9490082
C23: =RAND() -> 0.92584827 | D23: =IF(C23<($C$6-0.07)/(0.11-0.07),0.07+SQRT(C23*(0.11-0.07)*($C$6-0.07)),0.11-SQRT((1-C23)*(0.11-0.07)*(0.11-$C$6))) -> 0.10090311 | E23: =RAND() -> 0.68195655 | F23: =MIN( IF(E23<(0.02-0.01)/(0.03-0.01), 0.01+SQRT(E23*(0.03-0.01)*(0.02-0.01)), 0.03-SQRT((1-E23)*(0.03-0.01)*(0.03-0.02)) ), D23-0.005 ) -> 0.022024494 | G23: =$C$11/(1+D23)^1 +$D$11/(1+D23)^2 +$E$11/(1+D23)^3 +$F$11/(1+D23)^4 +$G$11/(1+D23)^5 +$H$11/(1+D23)^6 +$I$11/(1+D23)^7 + ( $I$11*(1+F23)/(D23-F23) )/(1+D23)^7 -> 208.97569 | H23: =(G23+DCF!$D$40+DCF!$D$41+DCF!$D$42-DCF!$D$43-DCF!$D$44)/DCF!$C$35 -> 1.8215526
C24: =RAND() -> 0.47661566 | D24: =IF(C24<($C$6-0.07)/(0.11-0.07),0.07+SQRT(C24*(0.11-0.07)*($C$6-0.07)),0.11-SQRT((1-C24)*(0.11-0.07)*(0.11-$C$6))) -> 0.085831903 | E24: =RAND() -> 0.37058186 | F24: =MIN( IF(E24<(0.02-0.01)/(0.03-0.01), 0.01+SQRT(E24*(0.03-0.01)*(0.02-0.01)), 0.03-SQRT((1-E24)*(0.03-0.01)*(0.03-0.02)) ), D24-0.005 ) -> 0.018609087 | G24: =$C$11/(1+D24)^1 +$D$11/(1+D24)^2 +$E$11/(1+D24)^3 +$F$11/(1+D24)^4 +$G$11/(1+D24)^5 +$H$11/(1+D24)^6 +$I$11/(1+D24)^7 + ( $I$11*(1+F24)/(D24-F24) )/(1+D24)^7 -> 251.70801 | H24: =(G24+DCF!$D$40+DCF!$D$41+DCF!$D$42-DCF!$D$43-DCF!$D$44)/DCF!$C$35 -> 2.0627329
C25: =RAND() -> 0.30221653 | D25: =IF(C25<($C$6-0.07)/(0.11-0.07),0.07+SQRT(C25*(0.11-0.07)*($C$6-0.07)),0.11-SQRT((1-C25)*(0.11-0.07)*(0.11-$C$6))) -> 0.082094329 | E25: =RAND() -> 0.92935067 | F25: =MIN( IF(E25<(0.02-0.01)/(0.03-0.01), 0.01+SQRT(E25*(0.03-0.01)*(0.02-0.01)), 0.03-SQRT((1-E25)*(0.03-0.01)*(0.03-0.02)) ), D25-0.005 ) -> 0.026241028 | G25: =$C$11/(1+D25)^1 +$D$11/(1+D25)^2 +$E$11/(1+D25)^3 +$F$11/(1+D25)^4 +$G$11/(1+D25)^5 +$H$11/(1+D25)^6 +$I$11/(1+D25)^7 + ( $I$11*(1+F25)/(D25-F25) )/(1+D25)^7 -> 294.4006 | H25: =(G25+DCF!$D$40+DCF!$D$41+DCF!$D$42-DCF!$D$43-DCF!$D$44)/DCF!$C$35 -> 2.3036889
C26: =RAND() -> 0.041525253 | D26: =IF(C26<($C$6-0.07)/(0.11-0.07),0.07+SQRT(C26*(0.11-0.07)*($C$6-0.07)),0.11-SQRT((1-C26)*(0.11-0.07)*(0.11-$C$6))) -> 0.074483104 | E26: =RAND() -> 0.50753261 | F26: =MIN( IF(E26<(0.02-0.01)/(0.03-0.01), 0.01+SQRT(E26*(0.03-0.01)*(0.02-0.01)), 0.03-SQRT((1-E26)*(0.03-0.01)*(0.03-0.02)) ), D26-0.005 ) -> 0.020075612 | G26: =$C$11/(1+D26)^1 +$D$11/(1+D26)^2 +$E$11/(1+D26)^3 +$F$11/(1+D26)^4 +$G$11/(1+D26)^5 +$H$11/(1+D26)^6 +$I$11/(1+D26)^7 + ( $I$11*(1+F26)/(D26-F26) )/(1+D26)^7 -> 312.16722 | H26: =(G26+DCF!$D$40+DCF!$D$41+DCF!$D$42-DCF!$D$43-DCF!$D$44)/DCF!$C$35 -> 2.4039633
C27: =RAND() -> 0.83555257 | D27: =IF(C27<($C$6-0.07)/(0.11-0.07),0.07+SQRT(C27*(0.11-0.07)*($C$6-0.07)),0.11-SQRT((1-C27)*(0.11-0.07)*(0.11-$C$6))) -> 0.096452921 | E27: =RAND() -> 0.73751377 | F27: =MIN( IF(E27<(0.02-0.01)/(0.03-0.01), 0.01+SQRT(E27*(0.03-0.01)*(0.02-0.01)), 0.03-SQRT((1-E27)*(0.03-0.01)*(0.03-0.02)) ), D27-0.005 ) -> 0.022754502 | G27: =$C$11/(1+D27)^1 +$D$11/(1+D27)^2 +$E$11/(1+D27)^3 +$F$11/(1+D27)^4 +$G$11/(1+D27)^5 +$H$11/(1+D27)^6 +$I$11/(1+D27)^7 + ( $I$11*(1+F27)/(D27-F27) )/(1+D27)^7 -> 223.79859 | H27: =(G27+DCF!$D$40+DCF!$D$41+DCF!$D$42-DCF!$D$43-DCF!$D$44)/DCF!$C$35 -> 1.9052127
C28: =RAND() -> 0.4529786 | D28: =IF(C28<($C$6-0.07)/(0.11-0.07),0.07+SQRT(C28*(0.11-0.07)*($C$6-0.07)),0.11-SQRT((1-C28)*(0.11-0.07)*(0.11-$C$6))) -> 0.08529219 | E28: =RAND() -> 0.80439675 | F28: =MIN( IF(E28<(0.02-0.01)/(0.03-0.01), 0.01+SQRT(E28*(0.03-0.01)*(0.02-0.01)), 0.03-SQRT((1-E28)*(0.03-0.01)*(0.03-0.02)) ), D28-0.005 ) -> 0.02374535 | G28: =$C$11/(1+D28)^1 +$D$11/(1+D28)^2 +$E$11/(1+D28)^3 +$F$11/(1+D28)^4 +$G$11/(1+D28)^5 +$H$11/(1+D28)^6 +$I$11/(1+D28)^7 + ( $I$11*(1+F28)/(D28-F28) )/(1+D28)^7 -> 269.29336 | H28: =(G28+DCF!$D$40+DCF!$D$41+DCF!$D$42-DCF!$D$43-DCF!$D$44)/DCF!$C$35 -> 2.1619842
... C2116: =RAND() -> 0.53298811 | D2116: =IF(C2116<($C$6-0.07)/(0.11-0.07),0.07+SQRT(C2116*(0.11-0.07)*($C$6-0.07)),0.11-SQRT((1-C2116)*(0.11-0.07)*(0.11-$C$6))) -> 0.087170517 | E2116: =RAND() -> 0.78424973 | F2116: =MIN( IF(E2116<(0.02-0.01)/(0.03-0.01), 0.01+SQRT(E2116*(0.03-0.01)*(0.02-0.01)), 0.03-SQRT((1-E2116)*(0.03-0.01)*(0.03-0.02)) ), D2116-0.005 ) -> 0.02343113 | G2116: =$C$11/(1+D2116)^1 +$D$11/(1+D2116)^2 +$E$11/(1+D2116)^3 +$F$11/(1+D2116)^4 +$G$11/(1+D2116)^5 +$H$11/(1+D2116)^6 +$I$11/(1+D2116)^7 + ( $I$11*(1+F2116)/(D2116-F2116) )/(1+D2116)^7 -> 259.97477 | H2116: =(G2116+DCF!$D$40+DCF!$D$41+DCF!$D$42-DCF!$D$43-DCF!$D$44)/DCF!$C$35 -> 2.1093903

Sheet Tuloslaskelma
A1: Income Statement | B1: 45657 | C1: 45291 | D1: 44926 | E1: 44561 | M1: 1000000
A2: TaxEffectOfUnusualItems | B2: 0 | C2: 0 | D2: -359435.69 | E2: 0
A3: TaxRateForCalcs | B3: 0.2393 | C3: 0.320825 | D3: 0.138244 | E3: 0.129039
A4: NormalizedEBITDA | B4: 20.75 | C4: 4.147 | D4: 56.463 | E4: 46.057
A5: TotalUnusualItems | B5: 0 | C5: 0 | D5: 0 | E5: 0
A6: TotalUnusualItemsExcludingGoodwill | B6: 0 | C6: 0 | D6: -2.6 | E6: 0
A7: NetIncomeFromContinuingOperationNetMinorityInterest | B7: 4.492 | C7: -3.331 | D7: 39.616 | E7: 34.32
A8: ReconciledDepreciation | B8: 2.535 | C8: 1.491 | D8: 4.18 | E8: 1.476
A9: ReconciledCostOfRevenue | B9: 27.979 | C9: 26.462 | D9: 28.155 | E9: 25.553
A10: EBITDA | B10: 20.75 | C10: 4.147 | D10: 56.463 | E10: 46.057
A11: EBIT | B11: 18.215 | C11: 2.656 | D11: 52.283 | E11: 44.581
A12: NetInterestIncome | B12: -4.112 | C12: -3.58 | D12: -6.216 | E12: -4.183
A13: InterestExpense | B13: 5.879 | C13: 4.548 | D13: 4.65 | E13: 3.981
... A49: OperatingRevenue | B49: 57.621 | C49: 49.305 | D49: 67.532 | E49: 52.784

Sheet Tase
A1: Balance Sheet | B1: 45657 | C1: 45291 | D1: 44926 | E1: 44561
A2: Treasury Shares Number | B2: 0.026299 | C2: 0.026299 | D2: 0.026299 | E2: 0.026299
A3: Ordinary Shares Number | B3: 176.85191 | C3: 158.82309 | D3: 158.02867 | E3: 156.59099
A4: Share Issued | B4: 176.87821 | C4: 158.84939 | D4: 158.05497 | E4: 156.61729
A5: Net Debt | B5: 11.465 | C5: 50.796 | D5: 36.131 | E5: 18.188
A6: Total Debt | B6: 102.533 | C6: 93.856 | D6: 92.966 | E6: 83.008
A7: Tangible Book Value | B7: 156.269 | C7: 105.3 | D7: 132.07 | E7: 110.004
A8: Invested Capital | B8: 298.4 | C8: 203.01 | D8: 229.758 | E8: 207.173
A9: Working Capital | B9: 90.884 | C9: 34.196 | D9: 61.369 | E9: 61.779
A10: Net Tangible Assets | B10: 156.269 | C10: 105.3 | D10: 132.07 | E10: 110.004
A11: Capital Lease Obligations | B11: 2.926 | C11: 4.043 | D11: 3.264 | E11: 1.613
A12: Common Stock Equity | B12: 198.793 | C12: 113.197 | D12: 140.056 | E12: 125.778
... A64: Cash Financial | B64: 76.756 | C64: 38.145 | D64: 53.571 | E64: 63.207

Sheet Rahavirtalaskelma
A1: Cash Flow Statement | B1: 45657 | C1: 45291 | D1: 44926 | E1: 44561
A2: Free Cash Flow | B2: 3.138 | C2: 12.058 | D2: 5.711 | E2: 10.885
A3: Repayment Of Debt | B3: -50.102 | C3: 0 | D3: -31.52 | E3: 0
A4: Issuance Of Debt | B4: 59.668 | C4: 0.011 | D4: 39.791 | E4: 0.14
A5: Issuance Of Capital Stock | B5: 0 | C5: 0 | D5: 0 | E5: 0.09
A6: Capital Expenditure | B6: -0.047 | C6: -0.026 | D6: -0.333 | E6: -0.14
A7: End Cash Position | B7: 90.142 | C7: 41.017 | D7: 55.944 | E7: 65.207
A8: Beginning Cash Position | B8: 41.017 | C8: 55.944 | D8: 65.207 | E8: 58.002
A9: Effect Of Exchange Rate Changes | B9: 0.153 | C9: -0.146 | D9: 0.244 | E9: 0
A10: Changes In Cash | B10: 48.972 | C10: -14.781 | D10: -9.507 | E10: 7.205
A11: Financing Cash Flow | B11: -13.705 | C11: -30.317 | D11: -17.992 | E11: -22.99
A12: Net Other Financing Charges | B12: 0 | C12: 0.031 | D12: -0.001 | E12: 0
... A46: Net Income From Continuing Operations | B46: 73.466 | C46: 3.392 | D46: 41.049 | E46: 35.362

Sheet Hinta
A1: Date | B1: Open | C1: High | D1: Low | E1: Close | F1: Volume | G1: Dividends | H1: Stock Splits
A2: 43160 | B2: 1.0293229 | C2: 1.0711353 | D2: 0.8854391 | E2: 0.8854391 | F2: 4990093 | G2: 0.11 | H2: 0
A3: 43191 | B3: 0.94533965 | C3: 1.0635071 | D3: 0.91251531 | E3: 1.0372477 | F3: 2528483 | G3: 0 | H3: 0
A4: 43221 | B4: 1.0372477 | C4: 1.0569422 | D4: 0.97685096 | E4: 0.97947687 | F4: 1366547 | G4: 0 | H4: 0
A5: 43252 | B5: 0.98078958 | C5: 1.0031101 | D5: 0.91907994 | E5: 0.92958373 | F5: 2155288 | G5: 0 | H5: 0
A6: 43282 | B6: 0.92039305 | C6: 0.99129354 | D6: 0.91514123 | E6: 0.97159898 | F6: 1426340 | G6: 0 | H6: 0
A7: 43313 | B7: 0.97422498 | C7: 1.0923925 | D7: 0.97159907 | E7: 1.0635071 | F7: 2313478 | G7: 0 | H7: 0
A8: 43344 | B8: 1.0648199 | C8: 1.0897664 | D8: 1.0516902 | E8: 1.0766367 | F8: 1093982 | G8: 0 | H8: 0
A9: 43374 | B9: 1.0766367 | C9: 1.0805756 | D9: 0.98472867 | E9: 1.0267438 | F9: 1565004 | G9: 0 | H9: 0
A10: 43405 | B10: 1.0451253 | C10: 1.0635069 | D10: 1.0044232 | E10: 1.0438124 | F10: 1611618 | G10: 0 | H10: 0
A11: 43435 | B11: 1.0438125 | C11: 1.0503774 | D11: 0.93483585 | E11: 0.96634716 | F11: 1697763 | G11: 0 | H11: 0
A12: 43466 | B12: 0.96634718 | C12: 1.1396594 | D12: 0.96634718 | E12: 1.1212778 | F12: 2716275 | G12: 0 | H12: 0
A13: 43497 | B13: 1.1252166 | C13: 1.1724836 | D13: 1.109461 | E13: 1.1724836 | F13: 2055495 | G13: 0 | H13: 0
... A97: 46054 | B97: 1.908 | C97: 1.934 | D97: 1.89 | E97: 1.914 | F97: 215880 | G97: 0 | H97: 0
